Workbook

Sheet Dashboard
B2: HXP Parent Builder Survey — Dashboard
B3: 1,189 parent responses collected before this year's trips
B5: =COUNTA(Insights!A2:A1190) | E5: =COUNTIF(Insights!A2:A1190,"Yes")/COUNTA(Insights!A2:A1190) | H5: =COUNTIF(Insights!A2:A1190,"No")/COUNTA(Insights!A2:A1190) | K5: =(COUNTIF(Insights!I2:I1190,"HXP Can Directly Fix")+COUNTIF(Insights!I2:I1190,"HXP Can Influence"))/SUM('Chart Data'!B38:B41) | N5: =COUNTIF(Insights!J2:J1190,TRUE)
B8: Total Responses | E8: Planning to Go (Yes) | H8: Not Going (No) | K8: "No" Reasons HXP Can Control | N8: Warm Leads (Soft 'No' Signal)
B47: Sample "Warm Lead" Quotes (parents who said no, but hinted they'd reconsider)
B48: “My job and time off. I would really love to go another year.”
B49: “Other obligations this year, but I hope to go in the future!”
B50: “My daughter needs the experience without me. But I would love to go!”
B51: “I would really like to go in the future. I am sending 3 teens this year. Finance is a part of why I am not going. And then it would be tough for me...”
B52: “I went last year and loved it. I will go again next year.”

Sheet Chart Data
A1: Backing data for the Dashboard charts - safe to leave visible, not meant for managers to read directly.
A3: Why Parents Don't Go
A4: Category | B4: Count
A5: Cost / Finances | B5: =COUNTIF(Insights!$F$2:$F$1190,"Cost / Finances")
A6: Work Schedule / Time Off | B6: =COUNTIF(Insights!$F$2:$F$1190,"Work Schedule / Time Off")
A7: Wants Child to Have Independent Experience | B7: =COUNTIF(Insights!$F$2:$F$1190,"Wants Child to Have Independent Experience")
A8: Other Kids / Family at Home | B8: =COUNTIF(Insights!$F$2:$F$1190,"Other Kids / Family at Home")
A9: Child Didn't Want Parent to Come | B9: =COUNTIF(Insights!$F$2:$F$1190,"Child Didn't Want Parent to Come")
A10: Another Family Member Going Instead | B10: =COUNTIF(Insights!$F$2:$F$1190,"Another Family Member Going Instead")
A11: Other / Uncategorized | B11: =COUNTIF(Insights!$F$2:$F$1190,"Other / Uncategorized")
A12: Not a Traveler / Personal Preference | B12: =COUNTIF(Insights!$F$2:$F$1190,"Not a Traveler / Personal Preference")
A13: Not Aware It Was an Option | B13: =COUNTIF(Insights!$F$2:$F$1190,"Not Aware It Was an Option")
A14: Other Life Commitment | B14: =COUNTIF(Insights!$F$2:$F$1190,"Other Life Commitment")
A15: Health / Physical / Age | B15: =COUNTIF(Insights!$F$2:$F$1190,"Health / Physical / Age")
A16: Family's Own Choice (No Elaboration) | B16: =COUNTIF(Insights!$F$2:$F$1190,"Family's Own Choice (No Elaboration)")
A17: Trip / Spot Was Already Full | B17: =COUNTIF(Insights!$F$2:$F$1190,"Trip / Spot Was Already Full")
A18: Not Needed | B18: =COUNTIF(Insights!$F$2:$F$1190,"Not Needed")
A21: Why Parents Do Go
A22: Category | B22: Count
A23: Wanted Shared Experience with Child | B23: =COUNTIF(Insights!$C$2:$C$1190,"Wanted Shared Experience with Child")
A24: Previous Positive Experience | B24: =COUNTIF(Insights!$C$2:$C$1190,"Previous Positive Experience")
A25: Faith / Service Motivation | B25: =COUNTIF(Insights!$C$2:$C$1190,"Faith / Service Motivation")
A26: Child/Spouse Asked Them to Go | B26: =COUNTIF(Insights!$C$2:$C$1190,"Child/Spouse Asked Them to Go")
A27: Family Member Was the Reason (No Elaboration) | B27: =COUNTIF(Insights!$C$2:$C$1190,"Family Member Was the Reason (No Elaboration)")
A28: Other / Uncategorized | B28: =COUNTIF(Insights!$C$2:$C$1190,"Other / Uncategorized")
A29: Love of Travel / Culture | B29: =COUNTIF(Insights!$C$2:$C$1190,"Love of Travel / Culture")
A30: Trust in the HXP Program | B30: =COUNTIF(Insights!$C$2:$C$1190,"Trust in the HXP Program")
A31: Concerned About Child Going Alone / Safety | B31: =COUNTIF(Insights!$C$2:$C$1190,"Concerned About Child Going Alone / Safety")
A32: Securing/Ensuring Child's Spot (Registration Timing) | B32: =COUNTIF(Insights!$C$2:$C$1190,"Securing/Ensuring Child's Spot (Registration Timing)")
A33: Personally Invited by HXP Staff/Trip Leader | B33: =COUNTIF(Insights!$C$2:$C$1190,"Personally Invited by HXP Staff/Trip Leader")
A36: Controllability
A37: Bucket | B37: Count
A38: HXP Can Directly Fix | B38: =COUNTIF(Insights!$I$2:$I$1190,"HXP Can Directly Fix")
A39: HXP Can Influence | B39: =COUNTIF(Insights!$I$2:$I$1190,"HXP Can Influence")
A40: Family's Own Choice | B40: =COUNTIF(Insights!$I$2:$I$1190,"Family's Own Choice")
A41: Unknown | B41: =COUNTIF(Insights!$I$2:$I$1190,"Unknown")
A44: Would-Help Themes (Maybe segment)
A45: Theme | B45: Count
A46: Cost / Financial Assistance | B46: =COUNTIF(Insights!$L$2:$L$1190,"Cost / Financial Assistance")
A47: Time / Scheduling | B47: =COUNTIF(Insights!$L$2:$L$1190,"Time / Scheduling")
...

Sheet Raw Data
A1: Are you planning on going as a Parent Builder? | B1: What influenced your decision to go? | C1: What influenced your decision not to go? | D1: What would help change your decision to go?
A2: No | C2: Good for my son to go without me.
A3: No | C3: Confidence in my kid
A4: No | C4: Not needed
A5: No | C5: I still have younger children to save for.
A6: No | C6: I think it is better for him
A7: No | C7: Want my son to have his own experience
A8: Yes | B8: I love teenagers, people in other cultures, and I love travel.
A9: Yes | B9: My husband wanted someone to go with our daughter, but I also wanted to experience this piece of heaven. I love teenagers!
A10: No | C10: The cost. Would have loved to go as a parent but it just wasn’t in our budget
A11: No | C11: Friends with experience
A12: Yes | B12: Could go with my son
A13: No | C13: Time away from work
A14: No | C14: Thought my daughter would have a better experience with out me
A15: No
A16: No
A17: No | C17: Our son needs an independent experience.
A18: No | C18: Money
A19: No | C19: I have 4 other kiddos at home that need me
A20: No | C20: cost
A21: No | C21: my daughter does not want me to go
A22: No | C22: Wanted my son to go alone
A23: No
A24: Yes | B24: My daughter asked me ro go
A25: No | C25: I want to fill up my time with something fun that makes me happy and is productive. I am also excited to experience the beauty of OBX
A26: No | C26: My job and time off. I would really love to go another year.
A27: No | C27: I wanted my daughter to have this experience on her own. I wanted her to rely on her group rather than me, to help her build stronger connections with other builders & the trip leaders.
A28: No | C28: Younger kids at home
A29: No | C29: Daughter asked me not to go
A30: No | C30: I really wanted to go, my son was cool with me going, but the Spirit said he needed to do this without me.
A31: No | C31: Work schedule is not compatible with the HXP schedule.
A32: No | C32: Cost & time away from other kids, also excited for my son to do this without me
A33: Maybe | D33: Cost
A34: No | C34: Private time for him
A35: No | C35: Work obligations
A36: No | C36: My child wanted to go on her own.
A37: Yes | B37: Previous trips
A38: No | C38: Time/ son coming home from a mission
A39: Yes | B39: I have been before and love it.
A40: Yes | B40: The Q&A night
...

Sheet Cleaned + Categorized
A1: Status | B1: Reason To Go | C1: Reason To Go - Category | D1: Reason To Go - All Tags | E1: Reason Not To Go | F1: Reason Not To Go - Category | G1: Reason Not To Go - All Tags | H1: What Would Help
A2: No | E2: Good for my son to go without me. | F2: Wants Child to Have Independent Experience | G2: Wants Child to Have Independent Experience
A3: No | E3: Confidence in my kid | F3: Wants Child to Have Independent Experience | G3: Wants Child to Have Independent Experience
A4: No | E4: Not needed | F4: Not Needed | G4: Not Needed
A5: No | E5: I still have younger children to save for. | F5: Other Kids / Family at Home | G5: Other Kids / Family at Home
A6: No | E6: I think it is better for him | F6: Wants Child to Have Independent Experience | G6: Wants Child to Have Independent Experience
A7: No | E7: Want my son to have his own experience | F7: Wants Child to Have Independent Experience | G7: Wants Child to Have Independent Experience
A8: Yes | B8: I love teenagers, people in other cultures, and I love travel. | C8: Love of Travel / Culture | D8: Love of Travel / Culture
A9: Yes | B9: My husband wanted someone to go with our daughter, but I also wanted to experience this piece of heaven. I love teenagers! | C9: Wanted Shared Experience with Child | D9: Wanted Shared Experience with Child
A10: No | E10: The cost. Would have loved to go as a parent but it just wasn't in our budget | F10: Cost / Finances | G10: Cost / Finances
A11: No | E11: Friends with experience | F11: Wants Child to Have Independent Experience | G11: Wants Child to Have Independent Experience
A12: Yes | B12: Could go with my son | C12: Other / Uncategorized
A13: No | E13: Time away from work | F13: Work Schedule / Time Off | G13: Work Schedule / Time Off
A14: No | E14: Thought my daughter would have a better experience with out me | F14: Wants Child to Have Independent Experience | G14: Wants Child to Have Independent Experience
A15: No
A16: No
A17: No | E17: Our son needs an independent experience. | F17: Wants Child to Have Independent Experience | G17: Wants Child to Have Independent Experience
A18: No | E18: Money | F18: Cost / Finances | G18: Cost / Finances
A19: No | E19: I have 4 other kiddos at home that need me | F19: Other Kids / Family at Home | G19: Other Kids / Family at Home
A20: No | E20: cost | F20: Cost / Finances | G20: Cost / Finances
A21: No | E21: my daughter does not want me to go | F21: Child Didn't Want Parent to Come | G21: Child Didn't Want Parent to Come
A22: No | E22: Wanted my son to go alone | F22: Wants Child to Have Independent Experience | G22: Wants Child to Have Independent Experience
A23: No
A24: Yes | B24: My daughter asked me ro go | C24: Child/Spouse Asked Them to Go | D24: Child/Spouse Asked Them to Go
A25: No | E25: I want to fill up my time with something fun that makes me happy and is productive. I am also excited to experience the beauty of OBX | F25: Work Schedule / Time Off | G25: Work Schedule / Time Off; Wants Child to Have Independent Experience
A26: No | E26: My job and time off. I would really love to go another year. | F26: Work Schedule / Time Off | G26: Work Schedule / Time Off
A27: No | E27: I wanted my daughter to have this experience on her own. I wanted her to rely on her group rather than me, to help her build stronger connections with other builders & the trip leaders. | F27: Wants Child to Have Independent Experience | G27: Wants Child to Have Independent Experience; Other Life Commitment
A28: No | E28: Younger kids at home | F28: Other Kids / Family at Home | G28: Other Kids / Family at Home
A29: No | E29: Daughter asked me not to go | F29: Child Didn't Want Parent to Come | G29: Child Didn't Want Parent to Come
A30: No | E30: I really wanted to go, my son was cool with me going, but the Spirit said he needed to do this without me. | F30: Wants Child to Have Independent Experience | G30: Wants Child to Have Independent Experience
A31: No | E31: Work schedule is not compatible with the HXP schedule. | F31: Work Schedule / Time Off | G31: Work Schedule / Time Off
A32: No | E32: Cost & time away from other kids, also excited for my son to do this without me | F32: Cost / Finances | G32: Cost / Finances; Work Schedule / Time Off; Other Kids / Family at Home; Wants Child to Have Independent Experience
A33: Maybe | H33: Cost
A34: No | E34: Private time for him | F34: Work Schedule / Time Off | G34: Work Schedule / Time Off
A35: No | E35: Work obligations | F35: Work Schedule / Time Off | G35: Work Schedule / Time Off
A36: No | E36: My child wanted to go on her own. | F36: Wants Child to Have Independent Experience | G36: Wants Child to Have Independent Experience
A37: Yes | B37: Previous trips | C37: Previous Positive Experience | D37: Previous Positive Experience
A38: No | E38: Time/ son coming home from a mission | F38: Work Schedule / Time Off | G38: Work Schedule / Time Off; Other Life Commitment
A39: Yes | B39: I have been before and love it. | C39: Previous Positive Experience | D39: Previous Positive Experience
A40: Yes | B40: The Q&A night | C40: Trust in the HXP Program | D40: Trust in the HXP Program
...

Sheet Insights
A1: Status | B1: Reason To Go | C1: Reason To Go - Category | D1: Reason To Go - All Tags | E1: Reason Not To Go | F1: Reason Not To Go - Category | G1: Reason Not To Go - All Tags | H1: What Would Help | I1: Not Going - Controllability | J1: Not Going - Soft No Signal | K1: Not Going - Reason Stack Count | L1: Would Help - Category | M1: Would Help - All Tags
A2: No | E2: Good for my son to go without me. | F2: Wants Child to Have Independent Experience | G2: Wants Child to Have Independent Experience | I2: Family's Own Choice | J2: FALSE | K2: 1
A3: No | E3: Confidence in my kid | F3: Wants Child to Have Independent Experience | G3: Wants Child to Have Independent Experience | I3: Family's Own Choice | J3: FALSE | K3: 1
A4: No | E4: Not needed | F4: Not Needed | G4: Not Needed | I4: Family's Own Choice | J4: FALSE | K4: 1
A5: No | E5: I still have younger children to save for. | F5: Other Kids / Family at Home | G5: Other Kids / Family at Home | I5: Family's Own Choice | J5: FALSE | K5: 1
A6: No | E6: I think it is better for him | F6: Wants Child to Have Independent Experience | G6: Wants Child to Have Independent Experience | I6: Family's Own Choice | J6: FALSE | K6: 1
A7: No | E7: Want my son to have his own experience | F7: Wants Child to Have Independent Experience | G7: Wants Child to Have Independent Experience | I7: Family's Own Choice | J7: FALSE | K7: 1
A8: Yes | B8: I love teenagers, people in other cultures, and I love travel. | C8: Love of Travel / Culture | D8: Love of Travel / Culture | J8: FALSE | K8: 0
A9: Yes | B9: My husband wanted someone to go with our daughter, but I also wanted to experience this piece of heaven. I love teenagers! | C9: Wanted Shared Experience with Child | D9: Wanted Shared Experience with Child | J9: FALSE | K9: 0
A10: No | E10: The cost. Would have loved to go as a parent but it just wasn't in our budget | F10: Cost / Finances | G10: Cost / Finances | I10: HXP Can Directly Fix | J10: FALSE | K10: 1
A11: No | E11: Friends with experience | F11: Wants Child to Have Independent Experience | G11: Wants Child to Have Independent Experience | I11: Family's Own Choice | J11: FALSE | K11: 1
A12: Yes | B12: Could go with my son | C12: Other / Uncategorized | J12: FALSE | K12: 0
A13: No | E13: Time away from work | F13: Work Schedule / Time Off | G13: Work Schedule / Time Off | I13: HXP Can Influence | J13: FALSE | K13: 1
A14: No | E14: Thought my daughter would have a better experience with out me | F14: Wants Child to Have Independent Experience | G14: Wants Child to Have Independent Experience | I14: Family's Own Choice | J14: FALSE | K14: 1
A15: No | J15: FALSE | K15: 0
A16: No | J16: FALSE | K16: 0
A17: No | E17: Our son needs an independent experience. | F17: Wants Child to Have Independent Experience | G17: Wants Child to Have Independent Experience | I17: Family's Own Choice | J17: FALSE | K17: 1
A18: No | E18: Money | F18: Cost / Finances | G18: Cost / Finances | I18: HXP Can Directly Fix | J18: FALSE | K18: 1
A19: No | E19: I have 4 other kiddos at home that need me | F19: Other Kids / Family at Home | G19: Other Kids / Family at Home | I19: Family's Own Choice | J19: FALSE | K19: 1
A20: No | E20: cost | F20: Cost / Finances | G20: Cost / Finances | I20: HXP Can Directly Fix | J20: FALSE | K20: 1
A21: No | E21: my daughter does not want me to go | F21: Child Didn't Want Parent to Come | G21: Child Didn't Want Parent to Come | I21: Family's Own Choice | J21: FALSE | K21: 1
A22: No | E22: Wanted my son to go alone | F22: Wants Child to Have Independent Experience | G22: Wants Child to Have Independent Experience | I22: Family's Own Choice | J22: FALSE | K22: 1
A23: No | J23: FALSE | K23: 0
A24: Yes | B24: My daughter asked me ro go | C24: Child/Spouse Asked Them to Go | D24: Child/Spouse Asked Them to Go | J24: FALSE | K24: 0
A25: No | E25: I want to fill up my time with something fun that makes me happy and is productive. I am also excited to experience the beauty of OBX | F25: Work Schedule / Time Off | G25: Work Schedule / Time Off; Wants Child to Have Independent Experience | I25: HXP Can Influence | J25: FALSE | K25: 2
A26: No | E26: My job and time off. I would really love to go another year. | F26: Work Schedule / Time Off | G26: Work Schedule / Time Off | I26: HXP Can Influence | J26: TRUE | K26: 1
A27: No | E27: I wanted my daughter to have this experience on her own. I wanted her to rely on her group rather than me, to help her build stronger connections with other builders & the trip leaders. | F27: Wants Child to Have Independent Experience | G27: Wants Child to Have Independent Experience; Other Life Commitment | I27: Family's Own Choice | J27: FALSE | K27: 2
A28: No | E28: Younger kids at home | F28: Other Kids / Family at Home | G28: Other Kids / Family at Home | I28: Family's Own Choice | J28: FALSE | K28: 1
A29: No | E29: Daughter asked me not to go | F29: Child Didn't Want Parent to Come | G29: Child Didn't Want Parent to Come | I29: Family's Own Choice | J29: FALSE | K29: 1
A30: No | E30: I really wanted to go, my son was cool with me going, but the Spirit said he needed to do this without me. | F30: Wants Child to Have Independent Experience | G30: Wants Child to Have Independent Experience | I30: Family's Own Choice | J30: FALSE | K30: 1
A31: No | E31: Work schedule is not compatible with the HXP schedule. | F31: Work Schedule / Time Off | G31: Work Schedule / Time Off | I31: HXP Can Influence | J31: FALSE | K31: 1
A32: No | E32: Cost & time away from other kids, also excited for my son to do this without me | F32: Cost / Finances | G32: Cost / Finances; Work Schedule / Time Off; Other Kids / Family at Home; Wants Child to Have Independent Experience | I32: HXP Can Directly Fix | J32: FALSE | K32: 4
A33: Maybe | H33: Cost | J33: FALSE | K33: 0 | L33: Cost / Financial Assistance | M33: Cost / Financial Assistance
A34: No | E34: Private time for him | F34: Work Schedule / Time Off | G34: Work Schedule / Time Off | I34: HXP Can Influence | J34: FALSE | K34: 1
A35: No | E35: Work obligations | F35: Work Schedule / Time Off | G35: Work Schedule / Time Off | I35: HXP Can Influence | J35: FALSE | K35: 1
A36: No | E36: My child wanted to go on her own. | F36: Wants Child to Have Independent Experience | G36: Wants Child to Have Independent Experience | I36: Family's Own Choice | J36: FALSE | K36: 1
A37: Yes | B37: Previous trips | C37: Previous Positive Experience | D37: Previous Positive Experience | J37: FALSE | K37: 0
A38: No | E38: Time/ son coming home from a mission | F38: Work Schedule / Time Off | G38: Work Schedule / Time Off; Other Life Commitment | I38: HXP Can Influence | J38: FALSE | K38: 2
A39: Yes | B39: I have been before and love it. | C39: Previous Positive Experience | D39: Previous Positive Experience | J39: FALSE | K39: 0
A40: Yes | B40: The Q&A night | C40: Trust in the HXP Program | D40: Trust in the HXP Program | J40: FALSE | K40: 0
...

Sheet Insights Summary
A1: Insight | B1: Metric | C1: Value
A2: 1. Controllability | B2: HXP Can Directly Fix | C2: 239
A3: 1. Controllability | B3: HXP Can Directly Fix (% of reasons given) | C3: 26.7
A4: 1. Controllability | B4: HXP Can Influence | C4: 222
A5: 1. Controllability | B5: HXP Can Influence (% of reasons given) | C5: 24.8
A6: 1. Controllability | B6: Family's Own Choice | C6: 418
A7: 1. Controllability | B7: Family's Own Choice (% of reasons given) | C7: 46.7
A8: 1. Controllability | B8: Unknown | C8: 17
A9: 1. Controllability | B9: Unknown (% of reasons given) | C9: 1.9
A10: 2. Soft No Signal | B10: Responses hinting at future interest | C10: 30
A11: 2. Soft No Signal | B11: % of 'No' reasons given | C11: 3.3
A12: 3. Reason Stack Count | B12: Single-theme responses | C12: 668
... A24: 4. Would-Help Themes | B24: Registration / Spot Availability | C24: 1
